telegram.vendor.ptb_urllib3.urllib3.connectionpool - WARNING - Retrying (Retry(total=2, connect=None, read=None, redirect=None)) after connection broken by 'NewConnectionError('<telegram.vendor.ptb_urllib3.urllib3.connection.VerifiedHTTPSConnection object at 0x00000000048E2F28>: Failed to establish a new connection: [Errno 11001] getaddrinfo failed',)': /bot408378429:AAFD2PRwO9Breirqf5FZyLZVvNhtVc25m0U/setWebhook
telegram.vendor.ptb_urllib3.urllib3.connectionpool - WARNING - Retrying (Retry(total=1, connect=None, read=None, redirect=None)) after connection broken by 'NewConnectionError('<telegram.vendor.ptb_urllib3.urllib3.connection.VerifiedHTTPSConnection object at 0x00000000048F11D0>: Failed to establish a new connection: [Errno 11001] getaddrinfo failed',)': /bot408378429:AAFD2PRwO9Breirqf5FZyLZVvNhtVc25m0U/setWebhook
telegram.vendor.ptb_urllib3.urllib3.connectionpool - WARNING - Retrying (Retry(total=0, connect=None, read=None, redirect=None)) after connection broken by 'NewConnectionError('<telegram.vendor.ptb_urllib3.urllib3.connection.VerifiedHTTPSConnection object at 0x00000000048F12E8>: Failed to establish a new connection: [Errno 11001] getaddrinfo failed',)': /bot408378429:AAFD2PRwO9Breirqf5FZyLZVvNhtVc25m0U/setWebhook
telegram.ext.updater - ERROR - error in bootstrap phase; try=0 max_retries=0
Traceback (most recent call last):
  File "C:\Python34\lib\site-packages\telegram\vendor\ptb_urllib3\urllib3\connection.py", line 141, in _new_conn
    (self.host, self.port), self.timeout, **extra_kw)
  File "C:\Python34\lib\site-packages\telegram\vendor\ptb_urllib3\urllib3\util\connection.py", line 60, in create_connection
    for res in socket.getaddrinfo(host, port, family, socket.SOCK_STREAM):
  File "C:\Python34\lib\socket.py", line 537, in getaddrinfo
    for res in _socket.getaddrinfo(host, port, family, type, proto, flags):
socket.gaierror: [Errno 11001] getaddrinfo failed

During handling of the above exception, another exception occurred:

Traceback (most recent call last):
  File "C:\Python34\lib\site-packages\telegram\vendor\ptb_urllib3\urllib3\connectionpool.py", line 617, in urlopen
    chunked=chunked)
  File "C:\Python34\lib\site-packages\telegram\vendor\ptb_urllib3\urllib3\connectionpool.py", line 360, in _make_request
    self._validate_conn(conn)
  File "C:\Python34\lib\site-packages\telegram\vendor\ptb_urllib3\urllib3\connectionpool.py", line 857, in _validate_conn
    super(HTTPSConnectionPool, self)._validate_conn(conn)
  File "C:\Python34\lib\site-packages\telegram\vendor\ptb_urllib3\urllib3\connectionpool.py", line 289, in _validate_conn
    conn.connect()
  File "C:\Python34\lib\site-packages\telegram\vendor\ptb_urllib3\urllib3\connection.py", line 284, in connect
    conn = self._new_conn()
  File "C:\Python34\lib\site-packages\telegram\vendor\ptb_urllib3\urllib3\connection.py", line 150, in _new_conn
    self, "Failed to establish a new connection: %s" % e)
telegram.vendor.ptb_urllib3.urllib3.exceptions.NewConnectionError: <telegram.vendor.ptb_urllib3.urllib3.connection.VerifiedHTTPSConnection object at 0x00000000048F1400>: Failed to establish a new connection: [Errno 11001] getaddrinfo failed

During handling of the above exception, another exception occurred:

Traceback (most recent call last):
  File "C:\Python34\lib\site-packages\telegram\utils\request.py", line 189, in _request_wrapper
    resp = self._con_pool.request(*args, **kwargs)
  File "C:\Python34\lib\site-packages\telegram\vendor\ptb_urllib3\urllib3\request.py", line 70, in request
    **urlopen_kw)
  File "C:\Python34\lib\site-packages\telegram\vendor\ptb_urllib3\urllib3\request.py", line 148, in request_encode_body
    return self.urlopen(method, url, **extra_kw)
  File "C:\Python34\lib\site-packages\telegram\vendor\ptb_urllib3\urllib3\poolmanager.py", line 244, in urlopen
    response = conn.urlopen(method, u.request_uri, **kw)
  File "C:\Python34\lib\site-packages\telegram\vendor\ptb_urllib3\urllib3\connectionpool.py", line 695, in urlopen
    **response_kw)
  File "C:\Python34\lib\site-packages\telegram\vendor\ptb_urllib3\urllib3\connectionpool.py", line 695, in urlopen
    **response_kw)
  File "C:\Python34\lib\site-packages\telegram\vendor\ptb_urllib3\urllib3\connectionpool.py", line 695, in urlopen
    **response_kw)
  File "C:\Python34\lib\site-packages\telegram\vendor\ptb_urllib3\urllib3\connectionpool.py", line 666, in urlopen
    _stacktrace=sys.exc_info()[2])
  File "C:\Python34\lib\site-packages\telegram\vendor\ptb_urllib3\urllib3\util\retry.py", line 376, in increment
    raise MaxRetryError(_pool, url, error or ResponseError(cause))
telegram.vendor.ptb_urllib3.urllib3.exceptions.MaxRetryError: HTTPSConnectionPool(host='api.telegram.org', port=443): Max retries exceeded with url: /bot408378429:AAFD2PRwO9Breirqf5FZyLZVvNhtVc25m0U/setWebhook (Caused by NewConnectionError('<telegram.vendor.ptb_urllib3.urllib3.connection.VerifiedHTTPSConnection object at 0x00000000048F1400>: Failed to establish a new connection: [Errno 11001] getaddrinfo failed',))

During handling of the above exception, another exception occurred:

Traceback (most recent call last):
  File "C:\Python34\lib\site-packages\telegram\ext\updater.py", line 385, in _bootstrap
    url=webhook_url, certificate=cert, allowed_updates=allowed_updates)
  File "C:\Python34\lib\site-packages\telegram\bot.py", line 57, in decorator
    result = func(self, *args, **kwargs)
  File "C:\Python34\lib\site-packages\telegram\bot.py", line 1653, in set_webhook
    result = self._request.post(url_, data, timeout=timeout)
  File "C:\Python34\lib\site-packages\telegram\utils\request.py", line 271, in post
    **urlopen_kwargs)
  File "C:\Python34\lib\site-packages\telegram\utils\request.py", line 195, in _request_wrapper
    raise NetworkError('urllib3 HTTPError {0}'.format(error))
telegram.error.NetworkError: urllib3 HTTPError HTTPSConnectionPool(host='api.telegram.org', port=443): Max retries exceeded with url: /bot408378429:AAFD2PRwO9Breirqf5FZyLZVvNhtVc25m0U/setWebhook (Caused by NewConnectionError('<telegram.vendor.ptb_urllib3.urllib3.connection.VerifiedHTTPSConnection object at 0x00000000048F1400>: Failed to establish a new connection: [Errno 11001] getaddrinfo failed',))
telegram.ext.updater - ERROR - unhandled exception
Traceback (most recent call last):
  File "C:\Python34\lib\site-packages\telegram\vendor\ptb_urllib3\urllib3\connection.py", line 141, in _new_conn
    (self.host, self.port), self.timeout, **extra_kw)
  File "C:\Python34\lib\site-packages\telegram\vendor\ptb_urllib3\urllib3\util\connection.py", line 60, in create_connection
    for res in socket.getaddrinfo(host, port, family, socket.SOCK_STREAM):
  File "C:\Python34\lib\socket.py", line 537, in getaddrinfo
    for res in _socket.getaddrinfo(host, port, family, type, proto, flags):
socket.gaierror: [Errno 11001] getaddrinfo failed

During handling of the above exception, another exception occurred:

Traceback (most recent call last):
  File "C:\Python34\lib\site-packages\telegram\vendor\ptb_urllib3\urllib3\connectionpool.py", line 617, in urlopen
    chunked=chunked)
  File "C:\Python34\lib\site-packages\telegram\vendor\ptb_urllib3\urllib3\connectionpool.py", line 360, in _make_request
    self._validate_conn(conn)
  File "C:\Python34\lib\site-packages\telegram\vendor\ptb_urllib3\urllib3\connectionpool.py", line 857, in _validate_conn
    super(HTTPSConnectionPool, self)._validate_conn(conn)
  File "C:\Python34\lib\site-packages\telegram\vendor\ptb_urllib3\urllib3\connectionpool.py", line 289, in _validate_conn
    conn.connect()
  File "C:\Python34\lib\site-packages\telegram\vendor\ptb_urllib3\urllib3\connection.py", line 284, in connect
    conn = self._new_conn()
  File "C:\Python34\lib\site-packages\telegram\vendor\ptb_urllib3\urllib3\connection.py", line 150, in _new_conn
    self, "Failed to establish a new connection: %s" % e)
telegram.vendor.ptb_urllib3.urllib3.exceptions.NewConnectionError: <telegram.vendor.ptb_urllib3.urllib3.connection.VerifiedHTTPSConnection object at 0x00000000048F1400>: Failed to establish a new connection: [Errno 11001] getaddrinfo failed

During handling of the above exception, another exception occurred:

Traceback (most recent call last):
  File "C:\Python34\lib\site-packages\telegram\utils\request.py", line 189, in _request_wrapper
    resp = self._con_pool.request(*args, **kwargs)
  File "C:\Python34\lib\site-packages\telegram\vendor\ptb_urllib3\urllib3\request.py", line 70, in request
    **urlopen_kw)
  File "C:\Python34\lib\site-packages\telegram\vendor\ptb_urllib3\urllib3\request.py", line 148, in request_encode_body
    return self.urlopen(method, url, **extra_kw)
  File "C:\Python34\lib\site-packages\telegram\vendor\ptb_urllib3\urllib3\poolmanager.py", line 244, in urlopen
    response = conn.urlopen(method, u.request_uri, **kw)
  File "C:\Python34\lib\site-packages\telegram\vendor\ptb_urllib3\urllib3\connectionpool.py", line 695, in urlopen
    **response_kw)
  File "C:\Python34\lib\site-packages\telegram\vendor\ptb_urllib3\urllib3\connectionpool.py", line 695, in urlopen
    **response_kw)
  File "C:\Python34\lib\site-packages\telegram\vendor\ptb_urllib3\urllib3\connectionpool.py", line 695, in urlopen
    **response_kw)
  File "C:\Python34\lib\site-packages\telegram\vendor\ptb_urllib3\urllib3\connectionpool.py", line 666, in urlopen
    _stacktrace=sys.exc_info()[2])
  File "C:\Python34\lib\site-packages\telegram\vendor\ptb_urllib3\urllib3\util\retry.py", line 376, in increment
    raise MaxRetryError(_pool, url, error or ResponseError(cause))
telegram.vendor.ptb_urllib3.urllib3.exceptions.MaxRetryError: HTTPSConnectionPool(host='api.telegram.org', port=443): Max retries exceeded with url: /bot408378429:AAFD2PRwO9Breirqf5FZyLZVvNhtVc25m0U/setWebhook (Caused by NewConnectionError('<telegram.vendor.ptb_urllib3.urllib3.connection.VerifiedHTTPSConnection object at 0x00000000048F1400>: Failed to establish a new connection: [Errno 11001] getaddrinfo failed',))

During handling of the above exception, another exception occurred:

Traceback (most recent call last):
  File "C:\Python34\lib\site-packages\telegram\ext\updater.py", line 147, in _thread_wrapper
    target(*args, **kwargs)
  File "C:\Python34\lib\site-packages\telegram\ext\updater.py", line 273, in _start_polling
    self._bootstrap(bootstrap_retries, clean=clean, webhook_url='', allowed_updates=None)
  File "C:\Python34\lib\site-packages\telegram\ext\updater.py", line 385, in _bootstrap
    url=webhook_url, certificate=cert, allowed_updates=allowed_updates)
  File "C:\Python34\lib\site-packages\telegram\bot.py", line 57, in decorator
    result = func(self, *args, **kwargs)
  File "C:\Python34\lib\site-packages\telegram\bot.py", line 1653, in set_webhook
    result = self._request.post(url_, data, timeout=timeout)
  File "C:\Python34\lib\site-packages\telegram\utils\request.py", line 271, in post
    **urlopen_kwargs)
  File "C:\Python34\lib\site-packages\telegram\utils\request.py", line 195, in _request_wrapper
    raise NetworkError('urllib3 HTTPError {0}'.format(error))
telegram.error.NetworkError: urllib3 HTTPError HTTPSConnectionPool(host='api.telegram.org', port=443): Max retries exceeded with url: /bot408378429:AAFD2PRwO9Breirqf5FZyLZVvNhtVc25m0U/setWebhook (Caused by NewConnectionError('<telegram.vendor.ptb_urllib3.urllib3.connection.VerifiedHTTPSConnection object at 0x00000000048F1400>: Failed to establish a new connection: [Errno 11001] getaddrinfo failed',))
telegram.ext.dispatcher - CRITICAL - stopping due to exception in another thread
telegram.ext.updater - WARNING - Exiting immediately!
